Workbook

Sheet Jan-22
D1: 44562
A2: Cliente | B2: Nº Cliente | C2: Nº Instalação | D2: Quant. | E2: % Desconto | F2: Data Fatura | G2: Conta
A3: Lucile Confecções LTDA | B3: 7005713839 | C3: 3003858507 | D3: 777 | E3: 0.1 | G3: 2
A4: CLL Hotel e Turismo | B4: 7008528502 | C4: 3001084033 | D4: 4106 | E4: 0.1 | G4: 1
A5: Academia Planeta Corpo | B5: 7200634170 | C5: 3012153634 | D5: 1780 | E5: 0.1 | F5: Dia 17 | G5: 2
A6: Academia Planeta Corpo | B6: 7005369021 | C6: 3011373971 | D6: 339 | E6: 0.1 | F6: Dia 17 | G6: 2
A7: MD Predial | B7: 7005492088 | C7: 3001449459 | D7: 620 | E7: 0.1 | G7: 2
A8: MD Predial | B8: 7005492088 | C8: 3011504476 | D8: 688 | E8: 0.1 | G8: 2
A9: MD Predial | B9: 7005492088 | C9: 3014340686 | D9: 557 | E9: 0.1 | G9: 2
A10: Fazenda Terra Mirante | B10: 7202158396 | C10: 3002906325 | D10: 195
A11: Irmãs Martins Andrade LTDA-ME | B11: 7005723073 | C11: 3002906806 | D11: 1910 | E11: 0.2 | F11: Dia 17 | G11: 2
A12: Supermercado Bela Vista | B12: 7009098124 | C12: 3003388708 | D12: 3532 | E12: 0.1 | G12: 1
A13: Supermercado Bela Vista | B13: 7009098124 | C13: 3010494037 | D13: 1949 | E13: 0.1 | G13: 1
A14: Supermercado Tia Lia | B14: 7005719624 | C14: 3001268572 | D14: 1181 | E14: 0.1 | G14: 1
A15: A M Lage | B15: 7005623640 | C15: 3002176022 | D15: 5639 | E15: 0.15 | G15: 2
A16: Contabilidade Rocha | B16: 7202048247 | C16: 3003586967 | D16: 86
A17: Contabilidade Rocha | B17: 7201379356 | C17: 3001450164
A18: Contabilidade Rocha | B18: 7202048247 | C18: 3000881551 | D18: 1017
A19: Hotel Itabira | B19: 7005634342 | C19: 3002906805 | D19: 2000 | E19: 0.2 | F19: Dia 17 | G19: 2
A20: Sindicato Metabase Itabira | B20: 7000047224 | C20: 3001450247 | D20: 1944 | E20: 0.1 | G20: 1
A21: Orbis Energia | B21: 7202360028 | C21: 3012107385 | D21: 483
A22: Panificadora Central | B22: 7005728190 | C22: 3002906524 | D22: 8674 | E22: 0.1 | F22: Dia 17 | G22: 1
A23: WB JS Comunicação | B23: 7010498067 | C23: 3013027271 | D23: 1669 | E23: 0.1 | G23: 2
A24: L e R Comercial | B24: 7005590706 | C24: 3006036124 | D24: 98 | E24: 0.1 | G24: 1
A25: L e R Comercial | B25: 7005590706 | C25: 3006066868 | D25: 28 | E25: 0.1 | G25: 1
A26: L e R Comercial | B26: 7005590706 | C26: 3012116454 | D26: 28 | E26: 0.1 | G26: 1
A27: Dominante Comercio de Calçados | B27: 7005707573 | C27: 3004831003 | D27: 45 | E27: 0.1 | G27: 1
A28: Dominante Comercio de Calçados | B28: 7005707573 | C28: 3004831005 | E28: 0.1 | G28: 1
A29: Dominante Comercio de Calçados | B29: 7005707573 | C29: 3006425617 | D29: 634 | E29: 0.1 | G29: 1
A30: ART Pão de Itabira | B30: 7005530163 | C30: 3003562994 | D30: 3007 | E30: 0.2 | G30: 2
A31: Hortifruti QueBom | B31: 7202402563 | C31: 3006700739 | D31: 4080 | E31: 0.15 | G31: 1
A32: Maria do Carmo Oliveira Olimpio | B32: 7202760807 | C32: 3012940288 | D32: 1982 | E32: 0.15 | G32: 2
A33: Jordana de Castro Comercio | B33: 7202482231 | C33: 3004607095 | D33: 295 | E33: 0.1 | G33: 2
A34: Jordana de Castro Comercio | B34: 7202482231 | C34: 3005534144 | D34: 139 | E34: 0.1 | G34: 2
C35: TOTAL | D35: =SUM(D3:D34) -> 49482

Sheet Fev-22
D1: 44593
A2: Cliente | B2: Nº Cliente | C2: Nº Instalação | D2: Quant. | E2: % Desconto | F2: Data Fatura | G2: Conta
A3: Lucile Confecções LTDA | B3: 7005713839 | C3: 3003858507 | D3: 1330 | E3: 0.1 | G3: 2
A4: CLL Hotel e Turismo | B4: 7008528502 | C4: 3001084033 | D4: 5354 | E4: 0.1 | G4: 1
A5: Academia Planeta Corpo | B5: 7200634170 | C5: 3012153634 | D5: 1892 | E5: 0.1 | F5: Dia 17 | G5: 2
A6: Academia Planeta Corpo | B6: 7005369021 | C6: 3011373971 | D6: 183 | E6: 0.1 | F6: Dia 17 | G6: 2
A7: MD Predial | B7: 7005492088 | C7: 3001449459 | D7: 620 | E7: 0.1 | G7: 2
A8: MD Predial | B8: 7005492088 | C8: 3011504476 | D8: 818 | E8: 0.1 | G8: 2
A9: MD Predial | B9: 7005492088 | C9: 3014340686 | D9: 733 | E9: 0.1 | G9: 2
A10: Fazenda Terra Mirante | B10: 7202158396 | C10: 3002906325 | D10: 257
A11: Irmãs Martins Andrade LTDA-ME | B11: 7005723073 | C11: 3002906806 | D11: 2143 | E11: 0.2 | F11: Dia 17 | G11: 2
A12: Supermercado Bela Vista | B12: 7009098124 | C12: 3003388708 | D12: 4803 | E12: 0.1 | G12: 1
A13: Supermercado Bela Vista | B13: 7009098124 | C13: 3010494037 | D13: 2566 | E13: 0.1 | G13: 1
A14: Supermercado Tia Lia | B14: 7005719624 | C14: 3001268572 | D14: 1525 | E14: 0.1 | G14: 1
A15: A M Lage | B15: 7005623640 | C15: 3002176022 | D15: 5982 | E15: 0.15 | G15: 2
A16: Contabilidade Rocha | B16: 7202048247 | C16: 3003586967 | D16: 110
A17: Contabilidade Rocha | B17: 7201379356 | C17: 3001450164
A18: Contabilidade Rocha | B18: 7202048247 | C18: 3000881551 | D18: 1259
A19: Hotel Itabira | B19: 7005634342 | C19: 3002906805 | D19: 2400 | E19: 0.2 | F19: Dia 17 | G19: 2
A20: Sindicato Metabase Itabira | B20: 7000047224 | C20: 3001450247 | D20: 2958 | E20: 0.1 | G20: 1
A21: Orbis Energia | B21: 7202360028 | C21: 3012107385 | D21: 546
A22: Panificadora Central | B22: 7005728190 | C22: 3002906524 | D22: 11298 | E22: 0.1 | F22: Dia 17 | G22: 1
A23: WB JS Comunicação | B23: 7010498067 | C23: 3013027271 | D23: 1983 | E23: 0.1 | G23: 2
A24: L e R Comercial | B24: 7005590706 | C24: 3006036124 | D24: 165 | E24: 0.1 | G24: 1
A25: L e R Comercial | B25: 7005590706 | C25: 3006066868 | D25: 37 | E25: 0.1 | G25: 1
A26: L e R Comercial | B26: 7005590706 | C26: 3012116454 | D26: 37 | E26: 0.1 | G26: 1
A27: Dominante Comercio de Calçados | B27: 7005707573 | C27: 3004831003 | D27: 37 | E27: 0.1 | G27: 1
A28: Dominante Comercio de Calçados | B28: 7005707573 | C28: 3004831005 | D28: 0 | E28: 0.1 | G28: 1
A29: Dominante Comercio de Calçados | B29: 7005707573 | C29: 3006425617 | D29: 0 | E29: 0.1 | G29: 1
A30: ART Pão de Itabira | B30: 7005530163 | C30: 3003562994 | D30: 3533 | E30: 0.2 | G30: 2
A31: Hortifruti QueBom | B31: 7202402563 | C31: 3006700739 | D31: 4407 | E31: 0.15 | G31: 1
A32: Maria do Carmo Oliveira Olimpio | B32: 7202760807 | C32: 3012940288 | D32: 2070 | E32: 0.15 | G32: 2
A33: Jordana de Castro Comercio | B33: 7202482231 | C33: 3004607095 | D33: 367 | E33: 0.1 | G33: 2
A34: Jordana de Castro Comercio | B34: 7202482231 | C34: 3005534144 | D34: 183 | E34: 0.1 | G34: 2
C35: TOTAL | D35: =SUM(D3:D34) -> 59596

Sheet Mar-22
D1: 44621
A2: Cliente | B2: Nº Cliente | C2: Nº Instalação | D2: Quant. | E2: % Desconto | F2: Data Fatura | G2: Conta
A3: Lucile Confecções LTDA | B3: 7005713839 | C3: 3003858507 | D3: 686 | E3: 0.1 | G3: 2
A4: CLL Hotel e Turismo | B4: 7008528502 | C4: 3001084033 | D4: 4330 | E4: 0.1 | G4: 1
A5: Academia Planeta Corpo | B5: 7200634170 | C5: 3012153634 | D5: 642 | E5: 0.1 | F5: Dia 17 | G5: 2
A6: Academia Planeta Corpo | B6: 7005369021 | C6: 3011373971 | D6: 173 | E6: 0.1 | F6: Dia 17 | G6: 2
A7: MD Predial | B7: 7005492088 | C7: 3001449459 | D7: 620 | E7: 0.1 | G7: 2
A8: MD Predial | B8: 7005492088 | C8: 3011504476 | D8: 781 | E8: 0.1 | G8: 2
A9: MD Predial | B9: 7005492088 | C9: 3014340686 | D9: 691 | E9: 0.1 | G9: 2
A10: Fazenda Terra Mirante | B10: 7202158396 | C10: 3002906325 | D10: 242
A11: Irmãs Martins Andrade LTDA-ME | B11: 7005723073 | C11: 3002906806 | D11: 2219 | E11: 0.2 | F11: Dia 17 | G11: 2
A12: Supermercado Bela Vista | B12: 7009098124 | C12: 3003388708 | D12: 3870 | E12: 0.1 | G12: 1
A13: Supermercado Bela Vista | B13: 7009098124 | C13: 3010494037 | D13: 2419 | E13: 0.1 | G13: 1
A14: Supermercado Tia Lia | B14: 7005719624 | C14: 3001268572 | D14: 1453 | E14: 0.1 | G14: 1
A15: A M Lage | B15: 7005623640 | C15: 3002176022 | D15: 6216 | E15: 0.15 | G15: 2
A16: Contabilidade Rocha | B16: 7202048247 | C16: 3003586967 | D16: 104
A17: Contabilidade Rocha | B17: 7201379356 | C17: 3001450164
A18: Contabilidade Rocha | B18: 7202048247 | C18: 3000881551 | D18: 1244
A19: Hotel Itabira | B19: 7005634342 | C19: 3002906805 | D19: 2600 | E19: 0.2 | F19: Dia 17 | G19: 2
A20: Sindicato Metabase Itabira | B20: 7000047224 | C20: 3001450247 | D20: 2070 | E20: 0.1 | G20: 1
A21: Orbis Energia | B21: 7202360028 | C21: 3012107385 | D21: 352
A22: Panificadora Central | B22: 7005728190 | C22: 3002906524 | D22: 6480 | E22: 0.1 | F22: Dia 17 | G22: 1
A23: WB JS Comunicação | B23: 7010498067 | C23: 3013027271 | D23: 1881 | E23: 0.1 | G23: 2
A24: L e R Comercial | B24: 7005590706 | C24: 3006036124 | D24: 38 | E24: 0.1 | G24: 1
A25: L e R Comercial | B25: 7005590706 | C25: 3006066868 | D25: 35 | E25: 0.1 | G25: 1
A26: L e R Comercial | B26: 7005590706 | C26: 3012116454 | D26: 35 | E26: 0.1 | G26: 1
A27: Dominante Comercio de Calçados | B27: 7005707573 | C27: 3004831003 | D27: 35 | E27: 0.1 | G27: 1
A28: Dominante Comercio de Calçados | B28: 7005707573 | C28: 3004831005 | D28: 0 | E28: 0.1 | G28: 1
A29: Dominante Comercio de Calçados | B29: 7005707573 | C29: 3006425617 | D29: 0 | E29: 0.1 | G29: 1
A30: ART Pão de Itabira | B30: 7005530163 | C30: 3003562994 | D30: 4036 | E30: 0.2 | G30: 2
A31: Hortifruti QueBom | B31: 7202402563 | C31: 3006700739 | D31: 4901 | E31: 0.15 | G31: 1
A32: Maria do Carmo Oliveira Olimpio | B32: 7202760807 | C32: 3012940288 | D32: 2464 | E32: 0.15 | G32: 2
A33: Jordana de Castro Comercio | B33: 7202482231 | C33: 3004607095 | D33: 346 | E33: 0.1 | G33: 2
A34: Jordana de Castro Comercio | B34: 7202482231 | C34: 3005534144 | D34: 173 | E34: 0.1 | G34: 2
C35: TOTAL | D35: =SUM(D3:D34) -> 51136

Sheet Abril-22
D1: 44652
A2: Cliente | B2: Nº Cliente | C2: Nº Instalação | D2: Quant. | E2: % Desconto | F2: Data Fatura | G2: Conta
A3: Lucile Confecções LTDA | B3: 7005713839 | C3: 3003858507 | D3: 3653 | E3: 0.1 | G3: 2
A4: CLL Hotel e Turismo | B4: 7008528502 | C4: 3001084033 | D4: 6369 | E4: 0.1 | G4: 1
A5: Academia Planeta Corpo | B5: 7200634170 | C5: 3012153634 | D5: 1930 | E5: 0.1 | F5: Dia 17 | G5: 2
A6: Academia Planeta Corpo | B6: 7005369021 | C6: 3011373971 | D6: 560 | E6: 0.1 | F6: Dia 17 | G6: 2
A7: MD Predial | B7: 7005492088 | C7: 3001449459 | D7: 800 | E7: 0.1 | G7: 2
A8: MD Predial | B8: 7005492088 | C8: 3011504476 | D8: 2700 | E8: 0.1 | G8: 2
A9: MD Predial | B9: 7005492088 | C9: 3014340686 | D9: 1995 | E9: 0.1 | G9: 2
A10: Fazenda Terra Mirante | B10: 7202158396 | C10: 3002906325 | D10: 374
A11: Irmãs Martins Andrade LTDA-ME | B11: 7005723073 | C11: 3002906806 | D11: 1944 | E11: 0.2 | F11: Dia 17 | G11: 2
A12: Supermercado Bela Vista | B12: 7009098124 | C12: 3003388708 | D12: 5180 | E12: 0.1 | G12: 1
A13: Supermercado Bela Vista | B13: 7009098124 | C13: 3010494037 | D13: 10795 | E13: 0.1 | G13: 1
A14: Supermercado Tia Lia | B14: 7005719624 | C14: 3001268572 | D14: 2990 | E14: 0.1 | G14: 1
A15: A M Lage | B15: 7005623640 | C15: 3002176022 | D15: 6384 | E15: 0.15 | G15: 2
A16: Contabilidade Rocha | B16: 7202048247 | C16: 3003586967 | D16: 162
A17: Contabilidade Rocha | B17: 7201379356 | C17: 3001450164
A18: Contabilidade Rocha | B18: 7202048247 | C18: 3000881551 | D18: 1417
A19: Hotel Itabira | B19: 7005634342 | C19: 3002906805 | D19: 2460 | E19: 0.2 | F19: Dia 17 | G19: 2
A20: Sindicato Metabase Itabira | B20: 7000047224 | C20: 3001450247 | D20: 3574 | E20: 0.1 | G20: 1
A21: Orbis Energia | B21: 7202360028 | C21: 3012107385 | D21: 197
A22: Panificadora Central | B22: 7005728190 | C22: 3002906524 | D22: 3494 | E22: 0.1 | F22: Dia 17 | G22: 1
A23: WB JS Comunicação | B23: 7010498067 | C23: 3013027271 | D23: 2480 | E23: 0.1 | G23: 2
A24: L e R Comercial | B24: 7005590706 | C24: 3006036124 | D24: 98 | E24: 0.1 | G24: 1
A25: L e R Comercial | B25: 7005590706 | C25: 3006066868 | E25: 0.1 | G25: 1
A26: L e R Comercial | B26: 7005590706 | C26: 3012116454 | E26: 0.1 | G26: 1
A27: Dominante Comercio de Calçados | B27: 7005707573 | C27: 3004831003 | E27: 0.1 | G27: 1
A28: Dominante Comercio de Calçados | B28: 7005707573 | C28: 3004831005 | E28: 0.1 | G28: 1
A29: Dominante Comercio de Calçados | B29: 7005707573 | C29: 3006425617 | E29: 0.1 | G29: 1
A30: ART Pão de Itabira | B30: 7005530163 | C30: 3003562994 | D30: 4242 | E30: 0.2 | G30: 2
A31: Hortifruti QueBom | B31: 7202402563 | C31: 3006700739 | D31: 4702 | E31: 0.15 | G31: 1
A32: Maria do Carmo Oliveira Olimpio | B32: 7202760807 | C32: 3012940288 | D32: 2501 | E32: 0.15 | G32: 2
A33: Jordana de Castro Comercio | B33: 7202482231 | C33: 3004607095 | D33: 432 | E33: 0.1 | G33: 2
A34: Jordana de Castro Comercio | B34: 7202482231 | C34: 3005534144 | D34: 216 | E34: 0.1 | G34: 2
C35: TOTAL | D35: =SUM(D3:D34) -> 71649

Sheet Maio-22
D1: 44682
A2: Cliente | B2: Nº Cliente | C2: Nº Instalação | D2: Quant. | E2: % Desconto | F2: Data Fatura | G2: Conta
A3: Lucile Confecções LTDA | B3: 7005713839 | C3: 3003858507 | D3: 2478 | E3: 0.1 | G3: 2
A4: CLL Hotel e Turismo | B4: 7008528502 | C4: 3001084033 | D4: 5504 | E4: 0.1 | G4: 1
A5: Academia Planeta Corpo | B5: 7200634170 | C5: 3012153634 | D5: 1523 | E5: 0.1 | G5: 2
A6: Academia Planeta Corpo | B6: 7005369021 | C6: 3011373971 | D6: 635 | E6: 0.1 | G6: 2
A7: MD Predial | B7: 7005492088 | C7: 3001449459 | D7: 700 | E7: 0.1 | G7: 2
A8: MD Predial | B8: 7005492088 | C8: 3011504476 | D8: 1840 | E8: 0.1 | G8: 2
A9: MD Predial | B9: 7005492088 | C9: 3014340686 | D9: 687 | E9: 0.1 | G9: 2
A10: Fazenda Terra Mirante | B10: 7202158396 | C10: 3002906325 | D10: 351
A11: Irmãs Martins Andrade LTDA-ME | B11: 7005723073 | C11: 3002906806 | D11: 2110 | E11: 0.2 | G11: 2
A12: Supermercado Bela Vista | B12: 7009098124 | C12: 3003388708 | D12: 4998 | E12: 0.1 | G12: 1
A13: Supermercado Bela Vista | B13: 7009098124 | C13: 3010494037 | D13: 9531 | E13: 0.1 | G13: 1
A14: Supermercado Tia Lia | B14: 7005719624 | C14: 3001268572 | D14: 2325 | E14: 0.1 | G14: 1
A15: A M Lage | B15: 7005623640 | C15: 3002176022 | D15: 5624 | E15: 0.15 | G15: 2
A16: Contabilidade Rocha | B16: 7202048247 | C16: 3003586967 | D16: 143
A17: Contabilidade Rocha | B17: 7201379356 | C17: 3001450164
A18: Contabilidade Rocha | B18: 7202048247 | C18: 3000881551 | D18: 1294
A19: Hotel Itabira | B19: 7005634342 | C19: 3002906805 | D19: 2540 | E19: 0.2 | G19: 2
A20: Sindicato Metabase Itabira | B20: 7000047224 | C20: 3001450247 | D20: 2361 | E20: 0.1 | G20: 1
A21: Orbis Energia | B21: 7202360028 | C21: 3012107385 | D21: 429
A22: Panificadora Central | B22: 7005728190 | C22: 3002906524 | E22: 0.1 | G22: 1
A23: WB JS Comunicação | B23: 7010498067 | C23: 3013027271 | D23: 2120 | E23: 0.1 | G23: 2
A24: L e R Comercial | B24: 7005590706 | C24: 3006036124 | D24: 67 | E24: 0.1 | G24: 1
A25: L e R Comercial | B25: 7005590706 | C25: 3006066868 | E25: 0.1 | G25: 1
A26: L e R Comercial | B26: 7005590706 | C26: 3012116454 | E26: 0.1 | G26: 1
A27: Dominante Comercio de Calçados | B27: 7005707573 | C27: 3004831003 | E27: 0.1 | G27: 1
A28: Dominante Comercio de Calçados | B28: 7005707573 | C28: 3004831005 | E28: 0.1 | G28: 1
A29: Dominante Comercio de Calçados | B29: 7005707573 | C29: 3006425617 | E29: 0.1 | G29: 1
A30: ART Pão de Itabira | B30: 7005530163 | C30: 3003562994 | D30: 4374 | E30: 0.2 | G30: 2
A31: Hortifruti QueBom | B31: 7202402563 | C31: 3006700739 | D31: 4172 | E31: 0.15 | G31: 1
A32: Maria do Carmo Oliveira Olimpio | B32: 7202760807 | C32: 3012940288 | D32: 1624 | E32: 0.15 | G32: 2
A33: Jordana de Castro Comercio | B33: 7202482231 | C33: 3004607095 | D33: 381 | E33: 0.1 | G33: 2
A34: Jordana de Castro Comercio | B34: 7202482231 | C34: 3005534144 | D34: 191 | E34: 0.1 | G34: 2
C35: TOTAL | D35: =SUM(D3:D34) -> 58002

Sheet Junho-22
D1: 44713
A2: Cliente | B2: Nº Cliente | C2: Nº Instalação | D2: Quant. | E2: % Desconto | F2: Data Fatura | G2: Conta
A3: Lucile Confecções LTDA | B3: 7005713839 | C3: 3003858507 | D3: 817 | E3: 0.1 | G3: 2
A4: CLL Hotel e Turismo | B4: 7008528502 | C4: 3001084033 | D4: 1160 | E4: 0.1 | G4: 1
A5: Academia Planeta Corpo | B5: 7200634170 | C5: 3012153634 | D5: 1160 | E5: 0.1 | G5: 2
A6: Academia Planeta Corpo | B6: 7005369021 | C6: 3011373971 | D6: 740 | E6: 0.1 | G6: 2
A7: MD Predial | B7: 7005492088 | C7: 3001449459 | D7: 620 | E7: 0.1 | G7: 2
A8: MD Predial | B8: 7005492088 | C8: 3011504476 | D8: 1600 | E8: 0.1 | G8: 2
A9: MD Predial | B9: 7005492088 | C9: 3014340686 | D9: 1309 | E9: 0.1 | G9: 2
A10: Fazenda Terra Mirante | B10: 7202158396 | C10: 3002906325 | D10: 413
A11: Irmãs Martins Andrade LTDA-ME | B11: 7005723073 | C11: 3002906806 | D11: 2094 | E11: 0.2 | G11: 2
A12: Supermercado Bela Vista | B12: 7009098124 | C12: 3003388708 | D12: 4687 | E12: 0.1 | G12: 1
A13: Supermercado Bela Vista | B13: 7009098124 | C13: 3010494037 | D13: 10779 | E13: 0.1 | G13: 1
A14: Supermercado Tia Lia | B14: 7005719624 | C14: 3001268572 | D14: 1913 | E14: 0.1 | G14: 1
A15: A M Lage | B15: 7005623640 | C15: 3002176022 | D15: 5896 | E15: 0.15 | G15: 2
A16: Contabilidade Rocha | B16: 7202048247 | C16: 3003586967 | D16: 162
A17: Contabilidade Rocha | B17: 7201379356 | C17: 3001450164
A18: Contabilidade Rocha | B18: 7202048247 | C18: 3000881551 | D18: 1328
A19: Hotel Itabira | B19: 7005634342 | C19: 3002906805 | D19: 2500 | E19: 0.2 | G19: 2
A20: Sindicato Metabase Itabira | B20: 7000047224 | C20: 3001450247 | D20: 1798 | E20: 0.15 | G20: 1
A21: Orbis Energia | B21: 7202360028 | C21: 3012107385 | D21: 357
A22: Panificadora Central | B22: 7005728190 | C22: 3002906524 | E22: 0.1 | G22: 1
A23: WB JS Comunicação | B23: 7010498067 | C23: 3013027271 | D23: 1920 | E23: 0.1 | G23: 2
A24: L e R Comercial | B24: 7005590706 | C24: 3006036124 | E24: 0.1 | G24: 1
A25: L e R Comercial | B25: 7005590706 | C25: 3006066868 | E25: 0.1 | G25: 1
A26: L e R Comercial | B26: 7005590706 | C26: 3012116454 | E26: 0.1 | G26: 1
A27: Dominante Comercio de Calçados | B27: 7005707573 | C27: 3004831003 | E27: 0.1 | G27: 1
A28: Dominante Comercio de Calçados | B28: 7005707573 | C28: 3004831005 | E28: 0.1 | G28: 1
A29: Dominante Comercio de Calçados | B29: 7005707573 | C29: 3006425617 | E29: 0.1 | G29: 1
A30: ART Pão de Itabira | B30: 7005530163 | C30: 3003562994 | D30: 3762 | E30: 0.2 | G30: 2
A31: Hortifruti QueBom | B31: 7202402563 | C31: 3006700739 | D31: 4364 | E31: 0.15 | G31: 1
A32: Maria do Carmo Oliveira Olimpio | B32: 7202760807 | C32: 3012940288 | D32: 1461 | E32: 0.15 | G32: 2
A33: Jordana de Castro Comercio | B33: 7202482231 | C33: 3004607095 | D33: 273 | E33: 0.2 | G33: 2
A34: Jordana de Castro Comercio | B34: 7202482231 | C34: 3005534144 | D34: 196 | E34: 0.2 | G34: 2
A35: Dr Redes (Consórcio) | B35: 7201768092 | C35: 3012189878 | D35: 741
A36: Sanati (Consórcio) | B36: 7201768092 | C36: 3001450194 | D36: 458 | E36: 0.2 | G36: 2
A37: Renato (Orbis) | B37: 7202360028 | C37: 3014183803 | D37: 238
A38: Somatis_Clinica Fisioterapia | B38: 7005466339 | C38: 3013791114 | D38: 0 | E38: 0.2 | G38: 2
A39: Somatis_Clinica Fisioterapia | B39: 7005466339 | C39: 3002619862 | E39: 0.2 | G39: 2
A40: Lanza Magalhães_Dr. Pet | B40: 7200135835 | C40: 3001450251 | E40: 0.15 | G40: 2
...

Sheet Julho-22
D1: 44743
A2: Cliente | B2: Nº Cliente | C2: Nº Instalação | D2: Quant. | E2: % Desconto | F2: Data Fatura | G2: Conta
A3: Lucile Confecções LTDA | B3: 7005713839 | C3: 3003858507 | D3: 601 | E3: 0.1 | G3: 2
A4: CLL Hotel e Turismo | B4: 7008528502 | C4: 3001084033 | D4: 5575 | E4: 0.1 | G4: 1
A5: Academia Planeta Corpo | B5: 7200634170 | C5: 3012153634 | D5: 960 | E5: 0.1 | G5: 2
A6: Academia Planeta Corpo | B6: 7005369021 | C6: 3011373971 | D6: 607 | E6: 0.1 | G6: 2
A7: MD Predial | B7: 7005492088 | C7: 3001449459 | D7: 780 | E7: 0.1 | G7: 2
A8: MD Predial | B8: 7005492088 | C8: 3011504476 | D8: 1385 | E8: 0.1 | G8: 2
A9: MD Predial | B9: 7005492088 | C9: 3014340686 | D9: 1729 | E9: 0.1 | G9: 2
A10: Fazenda Terra Mirante | B10: 7202158396 | C10: 3002906325 | D10: 358
A11: Irmãs Martins Andrade LTDA-ME | B11: 7005723073 | C11: 3002906806 | D11: 1972 | E11: 0.2 | G11: 2
A12: Supermercado Bela Vista | B12: 7009098124 | C12: 3003388708 | D12: 4780 | E12: 0.1 | G12: 1
A13: Supermercado Bela Vista | B13: 7009098124 | C13: 3010494037 | D13: 11106 | E13: 0.1 | G13: 1
A14: Supermercado Tia Lia | B14: 7005719624 | C14: 3001268572 | D14: 1359 | E14: 0.1 | G14: 1
A15: A M Lage | B15: 7005623640 | C15: 3002176022 | D15: 5172 | E15: 0.15 | G15: 2
A16: Contabilidade Rocha | B16: 7202048247 | C16: 3003586967 | D16: 167
A17: Contabilidade Rocha | B17: 7202048247 | C17: 3000881551 | D17: 1330
A18: Hotel Itabira | B18: 7005634342 | C18: 3002906805 | D18: 2300 | E18: 0.2 | G18: 2
A19: Sindicato Metabase Itabira | B19: 7000047224 | C19: 3001450247 | D19: 1680 | E19: 0.15 | G19: 1
A20: Orbis Energia | B20: 7202360028 | C20: 3012107385 | D20: 230
A21: WB JS Comunicação | B21: 7010498067 | C21: 3013027271 | D21: 1880 | E21: 0.1 | G21: 2
A22: ART Pão de Itabira | B22: 7005530163 | C22: 3003562994 | D22: 3932 | E22: 0.2 | G22: 2
A23: Hortifruti QueBom | B23: 7202402563 | C23: 3006700739 | D23: 3739 | E23: 0.15 | G23: 1
A24: Maria do Carmo Oliveira Olimpio | B24: 7202760807 | C24: 3012940288 | D24: 1341 | E24: 0.15 | G24: 2
A25: Jordana de Castro Comercio | B25: 7202482231 | C25: 3004607095 | D25: 273 | E25: 0.2 | G25: 2
A26: Jordana de Castro Comercio | B26: 7202482231 | C26: 3005534144 | D26: 197 | E26: 0.2 | G26: 2
A27: Dr Redes (Consórcio) | B27: 7201768092 | C27: 3012189878 | D27: 543
A28: Sanati (Consórcio) | B28: 7201768092 | C28: 3001450194 | D28: 437 | E28: 0.2 | G28: 2
A29: Renato (Orbis) | B29: 7202360028 | C29: 3014183803 | D29: 230
A30: Somatis_Clinica Fisioterapia | B30: 7005466339 | C30: 3013791114 | D30: 184 | E30: 0.2 | G30: 2
A31: Somatis_Clinica Fisioterapia | B31: 7005466339 | C31: 3002619862 | D31: 139 | E31: 0.2 | G31: 2
A32: Lanza Magalhães_Dr. Pet | B32: 7200135835 | C32: 3001450251 | D32: 332 | E32: 0.15 | G32: 2
A33: Celso Matozinho_Serra 1 (Consórcio) | B33: 7201768092 | C33: 3012262751 | D33: 0 | E33: 0.15 | G33: 2
A34: Celso Matozinho_Serra 2 (Consórcio) | B34: 7201768092 | C34: 3007395349 | D34: 0 | E34: 0.15 | G34: 2
A35: Celso Matozinho_BH (Consórcio) | B35: 7201768092 | C35: 3001780367 | D35: 0 | E35: 0.15 | G35: 2
A36: Celso Matozinho_Itabira (Consórcio) | B36: 7201768092 | C36: 3000914060 | D36: 544 | E36: 0.15 | G36: 2
A37: Agatha Rodrigues | B37: 7202806123 | C37: 3003198807 | D37: 1769 | E37: 0.15 | G37: 2
C38: TOTAL | D38: =SUM(D3:D26) -> 53453

Sheet Agosto-22
D1: 44774
A2: Cliente | B2: Nº Cliente | C2: Nº Instalação | D2: Quant. | E2: % Desconto | F2: Data Fatura | G2: Conta | H2: Faturado | I2: Enviado
A3: Lucile Confecções LTDA | B3: 7005713839 | C3: 3003858507 | D3: 638 | E3: 0.1 | F3: 10 | G3: 2 | H3: ok | I3: ok
A4: CLL Hotel e Turismo | B4: 7008528502 | C4: 3001084033 | D4: 5263 | E4: 0.1 | F4: 3 | G4: 1 | H4: ok | I4: ok
A5: Academia Planeta Corpo | B5: 7200634170 | C5: 3012153634 | D5: 1080 | E5: 0.1 | F5: 17 | G5: 2 | H5: ok | I5: ok
A6: Academia Planeta Corpo | B6: 7005369021 | C6: 3011373971 | D6: 438 | E6: 0.1 | F6: 17 | G6: 2 | H6: ok | I6: ok
A7: MD Predial | B7: 7005492088 | C7: 3001449459 | D7: 580 | E7: 0.1 | F7: 6.10 | G7: 2 | H7: ok | I7: ok
A8: MD Predial | B8: 7005492088 | C8: 3011504476 | D8: 1440 | E8: 0.1 | F8: 6.10 | G8: 2 | H8: ok | I8: ok
A9: MD Predial | B9: 7005492088 | C9: 3014340686 | D9: 1449 | E9: 0.1 | F9: 6.10 | G9: 2 | H9: ok | I9: ok
A10: Fazenda Terra Mirante | B10: 7202158396 | C10: 3002906325 | D10: 344 | H10: n/a | I10: n/a
A11: Irmãs Martins Andrade LTDA-ME | B11: 7005723073 | C11: 3002906806 | D11: 1889 | E11: 0.2 | F11: 17 | G11: 2 | H11: ok | I11: n/a
A12: Supermercado Bela Vista | B12: 7009098124 | C12: 3003388708 | D12: 4113 | E12: 0.1 | F12: 2 | G12: 1 | H12: ok | I12: ok
A13: Supermercado Bela Vista | B13: 7009098124 | C13: 3010494037 | D13: 10520 | E13: 0.1 | F13: 26 | G13: 1 | H13: ok | I13: ok
A14: Supermercado Tia Lia | B14: 7005719624 | C14: 3001268572 | D14: 909 | E14: 0.1 | F14: 9 | G14: 1 | H14: ok | I14: ok
A15: A M Lage | B15: 7005623640 | C15: 3002176022 | D15: 4986 | E15: 0.15 | F15: 17 | G15: 2 | H15: ok | I15: n/a
A16: Contabilidade Rocha | B16: 7202048247 | C16: 3003586967 | D16: 164 | H16: n/a | I16: n/a
A17: Contabilidade Rocha | B17: 7202048247 | C17: 3000881551 | D17: 1277 | H17: n/a | I17: n/a
A18: Hotel Itabira | B18: 7005634342 | C18: 3002906805 | D18: 2220 | E18: 0.2 | F18: 17 | G18: 2 | H18: ok | I18: ok
A19: Sindicato Metabase Itabira | B19: 7000047224 | C19: 3001450247 | D19: 1946 | E19: 0.15 | F19: 10 | G19: 1 | H19: ok | I19: ok
A20: Orbis Energia | B20: 7202360028 | C20: 3012107385 | D20: 274 | H20: n/a | I20: n/a
A21: WB JS Comunicação | B21: 7010498067 | C21: 3013027271 | D21: 1600 | E21: 0.1 | F21: 1 | G21: 2 | H21: ok | I21: ok
A22: ART Pão de Itabira | B22: 7005530163 | C22: 3003562994 | D22: 3808 | E22: 0.2 | F22: 3 | G22: 2 | H22: ok | I22: ok
A23: Hortifruti QueBom | B23: 7202402563 | C23: 3006700739 | D23: 4015 | E23: 0.15 | F23: 11 | G23: 1 | H23: ok | I23: ok
A24: Maria do Carmo Oliveira Olimpio | B24: 7202760807 | C24: 3012940288 | D24: 1699 | E24: 0.15 | F24: 17 | G24: 2 | H24: ok | I24: ok
A25: Jordana de Castro Comercio | B25: 7202482231 | C25: 3004607095 | D25: 251 | E25: 0.2 | F25: 6 | G25: 2 | H25: ok | I25: ok
A26: Jordana de Castro Comercio | B26: 7202482231 | C26: 3005534144 | D26: 175 | E26: 0.2 | F26: 6 | G26: 2 | H26: ok | I26: ok
A27: Dr Redes (Consórcio) | B27: 7201768092 | C27: 3012189878 | D27: 603 | H27: n/a | I27: n/a
A28: Sanati (Consórcio) | B28: 7201768092 | C28: 3001450194 | D28: 460 | E28: 0.2 | F28: 11 | G28: 2 | H28: ok
A29: Renato (Orbis) | B29: 7202360028 | C29: 3014183803 | D29: 228 | H29: n/a | I29: n/a
A30: Somatis_Clinica Fisioterapia | B30: 7005466339 | C30: 3013791114 | D30: 143 | E30: 0.2 | F30: 11 | G30: 2 | H30: ok | I30: ok
A31: Somatis_Clinica Fisioterapia | B31: 7005466339 | C31: 3002619862 | D31: 200 | E31: 0.2 | F31: 11 | G31: 2 | H31: ok | I31: ok
A32: Lanza Magalhães_Dr. Pet | B32: 7200135835 | C32: 3001450251 | D32: 378 | E32: 0.15 | F32: 17 | G32: 2 | H32: ok | I32: ok
A33: Celso Matozinho_Serra 1 (Consórcio) | B33: 7201768092 | C33: 3012262751 | D33: 264 | E33: 0.15 | F33: 11 | G33: 2 | H33: ok | I33: ok
A34: Celso Matozinho_Serra 2 (Consórcio) | B34: 7201768092 | C34: 3007395349 | D34: 500 | E34: 0.15 | F34: 11 | G34: 2 | H34: ok | I34: ok
A35: Celso Matozinho_BH (Consórcio) | B35: 7201768092 | C35: 3001780367 | D35: 208 | E35: 0.15 | F35: 11 | G35: 2 | H35: ok | I35: ok
A36: Celso Matozinho_Itabira (Consórcio) | B36: 7201768092 | C36: 3000914060 | D36: 361 | E36: 0.15 | F36: 11 | G36: 2 | H36: ok | I36: ok
A37: Agatha Rodrigues | B37: 7202806123 | C37: 3003198807 | D37: 2195 | E37: 0.15 | F37: 6 | G37: 2 | H37: ok | I37: ok
C38: TOTAL | D38: =SUM(D3:D26) -> 51078
A41: Cervejaria Portal da Canastra Ltda | B41: 7202649326 | C41: 3014018953 | E41: 0.15 | F41: 17 | J41: 3 meses
A42: Faculdade Maximum LTDA | B42: 7010221388 | C42: 3001348433 | E42: 0.2 | J42: 6 meses
...

Sheet Setembro-22
D1: 44805
A2: Cliente | B2: Nº Cliente | C2: Nº Instalação | D2: Quant. | E2: % Desconto | F2: Data Fatura | G2: Conta | H2: Faturado | I2: Enviado
A3: Lucile Confecções LTDA | B3: 7005713839 | C3: 3003858507 | D3: 686 | E3: 0.1 | G3: 2
A4: CLL Hotel e Turismo | B4: 7008528502 | C4: 3001084033 | D4: 5381 | E4: 0.1 | G4: 1
A5: Academia Planeta Corpo | B5: 7200634170 | C5: 3012153634 | D5: 1200 | E5: 0.1 | G5: 2
A6: Academia Planeta Corpo | B6: 7005369021 | C6: 3011373971 | D6: 557.33 | E6: 0.1 | G6: 2
A7: MD Predial | B7: 7005492088 | C7: 3001449459 | D7: 700 | E7: 0.1 | G7: 2
A8: MD Predial | B8: 7005492088 | C8: 3011504476 | D8: 1620 | E8: 0.1 | G8: 2
A9: MD Predial | B9: 7005492088 | C9: 3014340686 | D9: 1784 | E9: 0.1 | G9: 2
A10: Fazenda Terra Mirante | B10: 7202158396 | C10: 3002906325 | D10: 429 | H10: n/a | I10: n/a
A11: Irmãs Martins Andrade LTDA-ME | B11: 7005723073 | C11: 3002906806 | D11: 2321 | E11: 0.2 | G11: 2
A12: Supermercado Bela Vista | B12: 7009098124 | C12: 3003388708 | D12: 4392 | E12: 0.1 | F12: 44827 | G12: 1
A13: Supermercado Bela Vista | B13: 7009098124 | C13: 3010494037 | D13: 10920 | E13: 0.1 | F13: 44827 | G13: 1
A14: Supermercado Tia Lia | B14: 7005719624 | C14: 3001268572 | D14: 1323 | E14: 0.1 | G14: 1
A15: A M Lage | B15: 7005623640 | C15: 3002176022 | D15: 3617 | E15: 0.15 | F15: 17 | G15: 2
A16: Contabilidade Rocha | B16: 7202048247 | C16: 3003586967 | D16: 167 | H16: n/a | I16: n/a
A17: Contabilidade Rocha | B17: 7202048247 | C17: 3000881551 | D17: 1275 | H17: n/a | I17: n/a
A18: Hotel Itabira | B18: 7005634342 | C18: 3002906805 | D18: 2300 | E18: 0.2 | G18: 2
A19: Sindicato Metabase Itabira | B19: 7000047224 | C19: 3001450247 | D19: 2006 | E19: 0.15 | G19: 1
A20: Orbis Energia | B20: 7202360028 | C20: 3012107385 | D20: 315 | H20: n/a | I20: n/a
A21: WB JS Comunicação | B21: 7010498067 | C21: 3013027271 | D21: 2060 | E21: 0.1 | G21: 2
A22: ART Pão de Itabira | B22: 7005530163 | C22: 3003562994 | D22: 4168 | E22: 0.2 | G22: 2
A23: Hortifruti QueBom | B23: 7202402563 | C23: 3006700739 | D23: 3919 | E23: 0.15 | G23: 1
A24: Maria do Carmo Oliveira Olimpio | B24: 7202760807 | C24: 3012940288 | D24: 1828 | E24: 0.15 | G24: 2
A25: Jordana de Castro Comercio | B25: 7202482231 | C25: 3004607095 | D25: 266 | E25: 0.2 | G25: 2
A26: Jordana de Castro Comercio | B26: 7202482231 | C26: 3005534144 | D26: 194 | E26: 0.2 | G26: 2
A27: Dr Redes (Consórcio) | B27: 7201768092 | C27: 3012189878 | D27: 539 | H27: n/a | I27: n/a
A28: Sanati (Consórcio) | B28: 7201768092 | C28: 3001450194 | D28: 512 | E28: 0.2 | G28: 2
A29: Renato (Orbis) | B29: 7202360028 | C29: 3014183803 | D29: 257 | H29: n/a | I29: n/a
A30: Somatis_Clinica Fisioterapia | B30: 7005466339 | C30: 3013791114 | D30: 174 | E30: 0.2 | G30: 2
A31: Somatis_Clinica Fisioterapia | B31: 7005466339 | C31: 3002619862 | D31: 222 | E31: 0.2 | G31: 2
A32: Lanza Magalhães_Dr. Pet | B32: 7200135835 | C32: 3001450251 | D32: 468 | E32: 0.15 | G32: 2
A33: Celso Matozinho_Serra 1 (Consórcio) | B33: 7201768092 | C33: 3012262751 | D33: 610 | E33: 0.15 | G33: 2
A34: Celso Matozinho_Serra 2 (Consórcio) | B34: 7201768092 | C34: 3007395349 | D34: 249 | E34: 0.15 | G34: 2
A35: Celso Matozinho_BH (Consórcio) | B35: 7201768092 | C35: 3001780367 | D35: 236 | E35: 0.15 | G35: 2
A36: Celso Matozinho_Itabira (Consórcio) | B36: 7201768092 | C36: 3000914060 | D36: 355 | E36: 0.15 | G36: 2
A37: Agatha Rodrigues | B37: 7202806123 | C37: 3003198807 | D37: 2638 | E37: 0.15 | G37: 2
C38: TOTAL | D38: =SUM(D3:D26) -> 53428.33
A43: Marcelo Mendes | B43: 7205374759 | C43: 3002175890 | E43: 0.15 | F43: 17 | G43: ? | J43: 3 meses
A44: Carlos Roberto | B44: 7005439127 | C44: 3012512271 | E44: 0.15 | F44: 3 | G44: ? | J44: 3 meses
...

Sheet Outubro-22
D1: 44835 | J1: Custo da Tarifa PASEP | K1: Custo da Tarifa COFINS | L1: Custo da Tarifa c/ ICMS 18% | M1: Custo da Tarifa injetado s/ Pasep / Cofins | N1: Custo de Disponibilidade
A2: Cliente | B2: Nº Cliente | C2: Nº Instalação | D2: Quant. | E2: % Desconto | F2: Data Fatura | G2: Conta | I2: Custo da Tarifa (sem imposto) | J2: 0.0069 | K2: 0.0318
A3: Lucile Confecções LTDA | B3: 7005713839 | C3: 3003858507 | D3: 1116 | E3: 0.1 | G3: 2 | J3: =I3/(1-$K$2-$J$2) -> 0 | M3: =L3-(J3-I3) -> 0
A4: CLL Hotel e Turismo | B4: 7008528502 | C4: 3001084033 | D4: 5274 | E4: 0.1 | G4: 1 | I4: 0.65313 | J4: =I4/(1-$K$2-$J$2) -> 0.6794237 | L4: 0.74377646 | M4: =L4-(J4-I4) -> 0.71748276
A5: Academia Planeta Corpo | B5: 7200634170 | C5: 3012153634 | D5: 1300 | E5: 0.1 | G5: 2 | J5: =I5/(1-$K$2-$J$2) -> 0 | M5: =L5-(J5-I5) -> 0
A6: Academia Planeta Corpo | B6: 7005369021 | C6: 3011373971 | D6: 762 | E6: 0.1 | G6: 2 | I6: 0.65313 | J6: =I6/(1-$K$2-$J$2) -> 0.6794237 | L6: 0.74377646 | M6: =L6-(J6-I6) -> 0.71748276
A7: MD Predial | B7: 7005492088 | C7: 3001449459 | D7: 900 | E7: 0.1 | G7: 2 | J7: =I7/(1-$K$2-$J$2) -> 0 | M7: =L7-(J7-I7) -> 0
A8: MD Predial | B8: 7005492088 | C8: 3011504476 | D8: 1625 | E8: 0.1 | G8: 2 | J8: =I8/(1-$K$2-$J$2) -> 0 | M8: =L8-(J8-I8) -> 0
A9: MD Predial | B9: 7005492088 | C9: 3014340686 | D9: 1459 | E9: 0.1 | G9: 2 | I9: 0.65313 | J9: =I9/(1-$K$2-$J$2) -> 0.6794237 | L9: 0.74377646 | M9: =L9-(J9-I9) -> 0.71748276
A10: Fazenda Terra Mirante | B10: 7202158396 | C10: 3002906325 | D10: 357 | J10: =I10/(1-$K$2-$J$2) -> 0 | M10: =L10-(J10-I10) -> 0
A11: Irmãs Martins Andrade LTDA-ME | B11: 7005723073 | C11: 3002906806 | D11: 2064 | E11: 0.2 | G11: 2 | I11: 0.65313 | J11: =I11/(1-$K$2-$J$2) -> 0.6794237 | L11: 0.74377646 | M11: =L11-(J11-I11) -> 0.71748276
A12: Supermercado Bela Vista | B12: 7009098124 | C12: 3003388708 | D12: 3649 | E12: 0.1 | F12: 44827 | G12: 1 | I12: 0.65313 | J12: =I12/(1-$K$2-$J$2) -> 0.6794237 | L12: 0.74377646 | M12: =L12-(J12-I12) -> 0.71748276
A13: Supermercado Bela Vista | B13: 7009098124 | C13: 3010494037 | D13: 9708 | E13: 0.1 | F13: 44827 | G13: 1 | I13: 0.65313 | J13: =I13/(1-$K$2-$J$2) -> 0.6794237 | L13: 0.74377646 | M13: =L13-(J13-I13) -> 0.71748276
A14: Supermercado Tia Lia | B14: 7005719624 | C14: 3001268572 | D14: 856 | E14: 0.1 | G14: 1 | I14: 0.65313 | J14: =I14/(1-$K$2-$J$2) -> 0.6794237 | L14: 0.74377646 | M14: =L14-(J14-I14) -> 0.71748276
A15: A M Lage | B15: 7005623640 | C15: 3002176022 | D15: 3974 | E15: 0.15 | F15: 17 | G15: 2 | J15: =I15/(1-$K$2-$J$2) -> 0 | M15: =L15-(J15-I15) -> 0
A16: Contabilidade Rocha | B16: 7202048247 | C16: 3003586967 | D16: 189 | J16: =I16/(1-$K$2-$J$2) -> 0 | M16: =L16-(J16-I16) -> 0
A17: Contabilidade Rocha | B17: 7202048247 | C17: 3000881551 | D17: 1184 | J17: =I17/(1-$K$2-$J$2) -> 0 | M17: =L17-(J17-I17) -> 0
A18: Hotel Itabira | B18: 7005634342 | C18: 3002906805 | D18: 2260 | E18: 0.2 | G18: 2 | I18: 0.65313 | J18: =I18/(1-$K$2-$J$2) -> 0.6794237 | L18: 0.74377646 | M18: =L18-(J18-I18) -> 0.71748276
A19: Sindicato Metabase Itabira | B19: 7000047224 | C19: 3001450247 | D19: 2631 | E19: 0.15 | G19: 1 | J19: =I19/(1-$K$2-$J$2) -> 0 | M19: =L19-(J19-I19) -> 0
A20: Orbis Energia | B20: 7202360028 | C20: 3012107385 | D20: 380 | J20: =I20/(1-$K$2-$J$2) -> 0 | M20: =L20-(J20-I20) -> 0
A21: WB JS Comunicação | B21: 7010498067 | C21: 3013027271 | D21: 2020 | E21: 0.1 | G21: 2 | I21: 0.65313 | J21: =I21/(1-$K$2-$J$2) -> 0.6794237 | L21: 0.74377646 | M21: =L21-(J21-I21) -> 0.71748276
A22: ART Pão de Itabira | B22: 7005530163 | C22: 3003562994 | D22: 3698 | E22: 0.2 | G22: 2 | I22: 0.65313 | J22: =I22/(1-$K$2-$J$2) -> 0.6794237 | L22: 0.74377646 | M22: =L22-(J22-I22) -> 0.71748276
A23: Hortifruti QueBom | B23: 7202402563 | C23: 3006700739 | D23: 3928 | E23: 0.15 | G23: 1 | J23: =I23/(1-$K$2-$J$2) -> 0 | M23: =L23-(J23-I23) -> 0
A24: Hortifruti QueBom | B24: 7202402563 | C24: 3012307446 | D24: 2417 | E24: 0.15 | I24: 0.65313 | J24: =I24/(1-$K$2-$J$2) -> 0.6794237 | L24: 0.74377646 | M24: =L24-(J24-I24) -> 0.71748276
A25: Maria do Carmo Oliveira Olimpio | B25: 7202760807 | C25: 3012940288 | D25: 2166 | E25: 0.15 | G25: 2 | J25: =I25/(1-$K$2-$J$2) -> 0 | M25: =L25-(J25-I25) -> 0
A26: Jordana de Castro Comercio | B26: 7202482231 | C26: 3004607095 | D26: 320 | E26: 0.2 | G26: 2 | I26: 0.65313 | J26: =I26/(1-$K$2-$J$2) -> 0.6794237 | L26: 0.7432 | M26: =L26-(J26-I26) -> 0.7169063 | N26: 50 | O26: =(D26-N26)*M26 -> 193.5647 | P26: =O26-(O26*E26) -> 154.85176
A27: Jordana de Castro Comercio | B27: 7202482231 | C27: 3005534144 | D27: 191 | E27: 0.2 | G27: 2 | I27: 0.65313 | J27: =I27/(1-$K$2-$J$2) -> 0.6794237 | L27: 0.7432 | M27: =L27-(J27-I27) -> 0.7169063 | N27: 50 | O27: =(D27-N27)*M27 -> 101.08379 | P27: =O27-(O27*E27) -> 80.867031
A28: Dr Redes (Consórcio) | B28: 7201768092 | C28: 3012189878 | D28: 623 | J28: =I28/(1-$K$2-$J$2) -> 0 | M28: =L28-(J28-I28) -> 0
A29: Sanati (Consórcio) | B29: 7201768092 | C29: 3001450194 | D29: 358 | E29: 0.2 | G29: 2 | I29: 0.65313 | J29: =I29/(1-$K$2-$J$2) -> 0.6794237 | L29: 0.74377646 | M29: =L29-(J29-I29) -> 0.71748276
A30: Renato (Orbis) | B30: 7202360028 | C30: 3014183803 | D30: 188 | J30: =I30/(1-$K$2-$J$2) -> 0 | M30: =L30-(J30-I30) -> 0
A31: Somatis_Clinica Fisioterapia | B31: 7005466339 | C31: 3013791114 | D31: 237 | E31: 0.2 | G31: 2 | J31: =I31/(1-$K$2-$J$2) -> 0 | M31: =L31-(J31-I31) -> 0
A32: Somatis_Clinica Fisioterapia | B32: 7005466339 | C32: 3002619862 | D32: 350 | E32: 0.2 | G32: 2 | J32: =I32/(1-$K$2-$J$2) -> 0 | M32: =L32-(J32-I32) -> 0
A33: Lanza Magalhães_Dr. Pet | B33: 7200135835 | C33: 3001450251 | D33: 517 | E33: 0.15 | G33: 2 | J33: =I33/(1-$K$2-$J$2) -> 0 | M33: =L33-(J33-I33) -> 0
A34: Celso Matozinho_Serra 1 (Consórcio) | B34: 7201768092 | C34: 3012262751 | D34: 323 | E34: 0.15 | G34: 2 | J34: =I34/(1-$K$2-$J$2) -> 0 | M34: =L34-(J34-I34) -> 0
A35: Celso Matozinho_Serra 2 (Consórcio) | B35: 7201768092 | C35: 3007395349 | D35: 227 | E35: 0.15 | G35: 2 | J35: =I35/(1-$K$2-$J$2) -> 0 | M35: =L35-(J35-I35) -> 0
A36: Celso Matozinho_BH (Consórcio) | B36: 7201768092 | C36: 3001780367 | D36: 193 | E36: 0.15 | G36: 2 | J36: =I36/(1-$K$2-$J$2) -> 0 | M36: =L36-(J36-I36) -> 0
A37: Celso Matozinho_Itabira (Consórcio) | B37: 7201768092 | C37: 3000914060 | D37: 375 | E37: 0.15 | G37: 2 | I37: 0.65313 | J37: =I37/(1-$K$2-$J$2) -> 0.6794237 | L37: 0.74377646
A38: Agatha Rodrigues | B38: 7202806123 | C38: 3003198807 | D38: 2266 | E38: 0.15 | G38: 2 | I38: 0.65313 | J38: =I38/(1-$K$2-$J$2) -> 0.6794237 | L38: 0.74706632 | M38: =L38-(J38-I38) -> 0.72077262
A39: Marcelo Mendes | B39: 7205374759 | C39: 3002175890 | D39: 342 | E39: 0.15 | F39: 17 | G39: 2 | I39: 0.65313 | J39: =I39/(1-$K$2-$J$2) -> 0.6794237 | L39: 0.7432 | M39: =L39-(J39-I39) -> 0.7169063 | N39: 30 | O39: =(D39-N39)*M39 -> 223.67477 | P39: =O39-(O39*E39) -> 190.12355
A40: Carlos Roberto | B40: 7005439127 | C40: 3012512271 | D40: 348 | E40: 0.15 | F40: 3 | G40: 2 | I40: 0.65313 | J40: =I40/(1-$K$2-$J$2) -> 0.6794237 | L40: 0.7432 | M40: =L40-(J40-I40) -> 0.7169063 | N40: 50 | O40: =(D40-N40)*M40 -> 213.63808 | P40: =O40-(O40*E40) -> 181.59237
...

Sheet Novembro-22
D1: 44866
A2: Cliente | B2: Nº Cliente | C2: Nº Instalação | D2: Quant. | E2: % Desconto | F2: Data Fatura | G2: Conta | H2: Faturado | I2: Enviado
A3: Lucile Confecções LTDA | B3: 7005713839 | C3: 3003858507 | E3: 0.1 | G3: 2
A4: CLL Hotel e Turismo | B4: 7008528502 | C4: 3001084033 | E4: 0.1 | G4: 1
A5: Academia Planeta Corpo | B5: 7200634170 | C5: 3012153634 | E5: 0.1 | G5: 2
A6: Academia Planeta Corpo | B6: 7005369021 | C6: 3011373971 | E6: 0.1 | G6: 2
A7: MD Predial | B7: 7005492088 | C7: 3001449459 | E7: 0.1 | G7: 2
A8: MD Predial | B8: 7005492088 | C8: 3011504476 | E8: 0.1 | G8: 2
A9: MD Predial | B9: 7005492088 | C9: 3014340686 | E9: 0.1 | G9: 2
A10: Fazenda Terra Mirante | B10: 7202158396 | C10: 3002906325 | H10: n/a | I10: n/a
A11: Irmãs Martins Andrade LTDA-ME | B11: 7005723073 | C11: 3002906806 | E11: 0.2 | G11: 2
A12: Supermercado Bela Vista | B12: 7009098124 | C12: 3003388708 | E12: 0.1 | F12: 44827 | G12: 1
A13: Supermercado Bela Vista | B13: 7009098124 | C13: 3010494037 | E13: 0.1 | F13: 44827 | G13: 1
A14: Supermercado Tia Lia | B14: 7005719624 | C14: 3001268572 | E14: 0.1 | G14: 1
A15: A M Lage | B15: 7005623640 | C15: 3002176022 | E15: 0.15 | F15: 17 | G15: 2
A16: Contabilidade Rocha | B16: 7202048247 | C16: 3003586967 | H16: n/a | I16: n/a
A17: Contabilidade Rocha | B17: 7202048247 | C17: 3000881551 | H17: n/a | I17: n/a
A18: Hotel Itabira | B18: 7005634342 | C18: 3002906805 | E18: 0.2 | G18: 2
A19: Sindicato Metabase Itabira | B19: 7000047224 | C19: 3001450247 | E19: 0.15 | G19: 1
A20: Orbis Energia | B20: 7202360028 | C20: 3012107385 | H20: n/a | I20: n/a
A21: WB JS Comunicação | B21: 7010498067 | C21: 3013027271 | E21: 0.1 | G21: 2
A22: ART Pão de Itabira | B22: 7005530163 | C22: 3003562994 | E22: 0.2 | G22: 2
A23: Hortifruti QueBom | B23: 7202402563 | C23: 3006700739 | E23: 0.15 | G23: 1
A24: Maria do Carmo Oliveira Olimpio | B24: 7202760807 | C24: 3012940288 | E24: 0.15 | G24: 2
A25: Jordana de Castro Comercio | B25: 7202482231 | C25: 3004607095 | E25: 0.2 | G25: 2
A26: Jordana de Castro Comercio | B26: 7202482231 | C26: 3005534144 | E26: 0.2 | G26: 2
A27: Dr Redes (Consórcio) | B27: 7201768092 | C27: 3012189878 | H27: n/a | I27: n/a
A28: Sanati (Consórcio) | B28: 7201768092 | C28: 3001450194 | E28: 0.2 | G28: 2
A29: Renato (Orbis) | B29: 7202360028 | C29: 3014183803 | H29: n/a | I29: n/a
A30: Somatis_Clinica Fisioterapia | B30: 7005466339 | C30: 3013791114 | E30: 0.2 | G30: 2
A31: Somatis_Clinica Fisioterapia | B31: 7005466339 | C31: 3002619862 | E31: 0.2 | G31: 2
A32: Lanza Magalhães_Dr. Pet | B32: 7200135835 | C32: 3001450251 | E32: 0.15 | G32: 2
A33: Celso Matozinho_Serra 1 (Consórcio) | B33: 7201768092 | C33: 3012262751 | E33: 0.15 | G33: 2
A34: Celso Matozinho_Serra 2 (Consórcio) | B34: 7201768092 | C34: 3007395349 | E34: 0.15 | G34: 2
A35: Celso Matozinho_BH (Consórcio) | B35: 7201768092 | C35: 3001780367 | E35: 0.15 | G35: 2
A36: Celso Matozinho_Itabira (Consórcio) | B36: 7201768092 | C36: 3000914060 | E36: 0.15 | G36: 2
A37: Agatha Rodrigues | B37: 7202806123 | C37: 3003198807 | E37: 0.15 | G37: 2
A38: Marcelo Mendes | B38: 7205374759 | C38: 3002175890 | E38: 0.15 | F38: 17
A39: Carlos Roberto | B39: 7005439127 | C39: 3012512271 | E39: 0.15 | F39: 3
A40: Simonica Rodrigues | B40: 7200317399 | C40: 3011377412 | E40: 0.2 | F40: 8
...

Sheet Produção
A1: 2018 | E1: 2019 | I1: 2020
A2: Mês | B2: Produção Estimada | C2: Produção Efetiva | E2: Mês | F2: Produção Estimada | G2: Produção Efetiva | I2: Mês | J2: Produção Estimada | K2: Produção Efetiva
A3: Janeiro | B3: 33585 | E3: Janeiro | F3: 33585 | G3: =ROUND(36160*0.975,2) -> 35256 | I3: Janeiro | J3: 40813 | K3: 38688
A4: Fevereiro | B4: 32700 | E4: Fevereiro | F4: 32700 | G4: =ROUND(34800*0.975,2) -> 33930 | I4: Fevereiro | J4: 39741 | K4: 41020
A5: Março | B5: 34800 | E5: Março | F5: 34800 | G5: =+ROUND(29760*0.975,2) -> 29016 | I5: Março | J5: 39410 | K5: 30800
A6: Abril | B6: 34000 | E6: Abril | F6: 34000 | G6: =+ROUND(32880*0.975,2) -> 32058 | I6: Abril | J6: 36895 | K6: 31120
A7: Maio | B7: 34000 | E7: Maio | F7: 34000 | G7: 29200 | I7: Maio | J7: 36904 | K7: 35920
A8: Junho | B8: 34000 | E8: Junho | F8: 34000 | G8: 31434 | I8: Junho | J8: 35547 | K8: 43200
A9: Julho | B9: 35900 | E9: Julho | F9: 35900 | G9: 34008 | I9: Julho | J9: 38621 | K9: 38640
A10: Agosto | B10: 38000 | E10: Agosto | F10: 38000 | G10: 33360 | I10: Agosto | J10: 43317 | K10: 41280
A11: Setembro | B11: 35400 | E11: Setembro | F11: 35400 | G11: 34242 | I11: Setembro | J11: 38413 | K11: 49120
A12: Outubro | B12: 35200 | E12: Outubro | F12: 35200 | G12: 28470 | I12: Outubro | J12: 39665 | K12: 29000
A13: Novembro | B13: 31000 | E13: Novembro | F13: 31000 | G13: 29874 | I13: Novembro | J13: 34286
A14: Dezembro | B14: 31000 | C14: =ROUND(30560*0.975,2) -> 29796 | E14: Dezembro | F14: 31000 | G14: 34710 | I14: Dezembro | J14: 38384
A15: TOTAL | B15: =SUM(B3:B14) -> 409585 | E15: TOTAL | F15: =SUM(F3:F14) -> 409585 | G15: =SUM(G3:G14) -> 385558 | I15: TOTAL | J15: =SUM(J3:J14) -> 461996 | K15: =SUM(K3:K14) -> 378788

Sheet Simulador
H1: Usina | I1: Alexandre - CGH | J1: Funcesi | K1: Alttos | L1: Albuquerque | M1: Fenix - BL1 | N1: Fenix - BL3 | O1: Fenix - BL7
H2: ='Consumo Médio - Clientes'!BN3 -> 53430 | I2: ='Consumo Médio - Clientes'!AX172 -> 469700 | J2: ='Consumo Médio - Clientes'!AX171 -> 0 | K2: ='Consumo Médio - Clientes'!AX173 -> 12000 | L2: ='Consumo Médio - Clientes'!AX174 -> 12000 | M2: ='Consumo Médio - Clientes'!AX175 -> 1000 | N2: ='Consumo Médio - Clientes'!AX176 -> 1000 | O2: ='Consumo Médio - Clientes'!AX177 -> 1000
H3: UC 3013497957 | I3: UC 3013483817 | J3: UC 3009018668 | K3: UC 3007768063 | L3: UC 3014922778 | M3: UC 3013771324 | N3: UC 3013939291 | O3: UC 3013939295
A4: Cliente | B4: Nº Cliente | C4: Nº Instalação | D4: Consumo Médio | E4: % Atendido | F4: Energia Injetada | G4: Saldo GD | H4: % Saldo | I4: % Saldo | J4: % Saldo | K4: % Saldo | L4: % Saldo | M4: % Saldo | N4: % Saldo | O4: % Saldo
A5: ='Consumo Médio - Clientes'!A2 -> Lucile Confecções LTDA | B5: ='Consumo Médio - Clientes'!B2 -> 7005713839 | C5: ='Consumo Médio - Clientes'!C2 -> 3003858507 | D5: ='Consumo Médio - Clientes'!AX2 -> 3308 | E5: =F5/D5 -> 0.88834643 | F5: =SUM(H5*$H$2,I5*$I$2,J5*$J$2,$K$2*K5,$L$2*L5,M5*$M$2,N5*$N$2,O5*$O$2) -> 2938.65 | G5: ='Consumo Médio - Clientes'!AY2 -> 0 | H5: 0.055 | I5: 0 | J5: 0.05 | K5: 0 | L5: 0 | M5: 0 | N5: 0 | O5: 0
A6: ='Consumo Médio - Clientes'!A3 -> CLL Hotel e Turismo | B6: ='Consumo Médio - Clientes'!B3 -> 7008528502 | C6: ='Consumo Médio - Clientes'!C3 -> 3001084033 | D6: ='Consumo Médio - Clientes'!AX3 -> 7707 | E6: =F6/D6 -> 0.00069326586 | F6: =SUM(H6*$H$2,I6*$I$2,J6*$J$2,$K$2*K6,$L$2*L6,M6*$M$2,N6*$N$2,O6*$O$2) -> 5.343 | G6: ='Consumo Médio - Clientes'!AY3 -> 19766 | H6: 0.0001 | I6: 0 | J6: 0.1 | K6: 0 | L6: 0 | M6: 0 | N6: 0 | O6: 0
A7: ='Consumo Médio - Clientes'!A4 -> Academia Planeta Corpo | B7: ='Consumo Médio - Clientes'!B4 -> 7005369021 | C7: ='Consumo Médio - Clientes'!C4 -> 3011373971 | D7: ='Consumo Médio - Clientes'!AX4 -> 467 | E7: =F7/D7 -> 0.011441113 | F7: =SUM(H7*$H$2,I7*$I$2,J7*$J$2,$K$2*K7,$L$2*L7,M7*$M$2,N7*$N$2,O7*$O$2) -> 5.343 | G7: ='Consumo Médio - Clientes'!AY4 -> 1359 | H7: 0.0001 | I7: 0 | J7: 0 | K7: 0 | L7: 0 | M7: 0 | N7: 0 | O7: 0
A8: ='Consumo Médio - Clientes'!A5 -> MD Predial | B8: ='Consumo Médio - Clientes'!B5 -> 7005492088 | C8: ='Consumo Médio - Clientes'!C5 -> 3001449459 | D8: ='Consumo Médio - Clientes'!AX5 -> 1440 | E8: =F8/D8 -> 1.0545833 | F8: =SUM(H8*$H$2,I8*$I$2,J8*$J$2,$K$2*K8,$L$2*L8,M8*$M$2,N8*$N$2,O8*$O$2) -> 1518.6 | G8: ='Consumo Médio - Clientes'!AY5 -> 0 | H8: 0.02 | I8: 0 | J8: 0.1 | K8: 0 | L8: 0 | M8: 0.15 | N8: 0.15 | O8: 0.15
A9: ='Consumo Médio - Clientes'!A6 -> MD Predial | B9: ='Consumo Médio - Clientes'!B6 -> 7005492088 | C9: ='Consumo Médio - Clientes'!C6 -> 3011504476 | D9: ='Consumo Médio - Clientes'!AX6 -> 1867 | E9: =F9/D9 -> 1.0368238 | F9: =SUM(H9*$H$2,I9*$I$2,J9*$J$2,$K$2*K9,$L$2*L9,M9*$M$2,N9*$N$2,O9*$O$2) -> 1935.75 | G9: ='Consumo Médio - Clientes'!AY6 -> 127 | H9: 0.025 | I9: 0 | J9: 0.1 | K9: 0 | L9: 0 | M9: 0.2 | N9: 0.2 | O9: 0.2
A10: ='Consumo Médio - Clientes'!A7 -> MD Predial | B10: ='Consumo Médio - Clientes'!B7 -> 7005492088 | C10: ='Consumo Médio - Clientes'!C7 -> 3014340686 | D10: ='Consumo Médio - Clientes'!AX7 -> 1447 | E10: =F10/D10 -> 1.1531444 | F10: =SUM(H10*$H$2,I10*$I$2,J10*$J$2,$K$2*K10,$L$2*L10,M10*$M$2,N10*$N$2,O10*$O$2) -> 1668.6 | G10: ='Consumo Médio - Clientes'!AY7 -> 0 | H10: 0.02 | I10: 0 | J10: 0.1 | K10: 0 | L10: 0 | M10: 0.2 | N10: 0.2 | O10: 0.2
A11: ='Consumo Médio - Clientes'!A8 -> Fazenda Terra Mirante | B11: ='Consumo Médio - Clientes'!B8 -> 7202158396 | C11: ='Consumo Médio - Clientes'!C8 -> 3002906325 | D11: ='Consumo Médio - Clientes'!AX8 -> 388 | E11: =F11/D11 -> 0.68853093 | F11: =SUM(H11*$H$2,I11*$I$2,J11*$J$2,$K$2*K11,$L$2*L11,M11*$M$2,N11*$N$2,O11*$O$2) -> 267.15 | G11: ='Consumo Médio - Clientes'!AY8 -> 0 | H11: 0.005 | I11: 0 | J11: 0 | K11: 0 | L11: 0 | M11: 0 | N11: 0 | O11: 0
A12: ='Consumo Médio - Clientes'!A9 -> Irmãs Martins Andrade LTDA-ME | B12: ='Consumo Médio - Clientes'!B9 -> 7005723073 | C12: ='Consumo Médio - Clientes'!C9 -> 3002906806 | D12: ='Consumo Médio - Clientes'!AX9 -> 2262 | E12: =F12/D12 -> 0.6229443 | F12: =SUM(H12*$H$2,I12*$I$2,J12*$J$2,$K$2*K12,$L$2*L12,M12*$M$2,N12*$N$2,O12*$O$2) -> 1409.1 | G12: ='Consumo Médio - Clientes'!AY9 -> 4764 | H12: 0 | I12: 0.003 | J12: 0 | K12: 0 | L12: 0 | M12: 0 | N12: 0 | O12: 0
A13: ='Consumo Médio - Clientes'!A10 -> Supermercado Bela Vista | B13: ='Consumo Médio - Clientes'!B10 -> 7009098124 | C13: ='Consumo Médio - Clientes'!C10 -> 3003388708 | D13: ='Consumo Médio - Clientes'!AX10 -> 5293 | E13: =F13/D13 -> 0.88739845 | F13: =SUM(H13*$H$2,I13*$I$2,J13*$J$2,$K$2*K13,$L$2*L13,M13*$M$2,N13*$N$2,O13*$O$2) -> 4697 | G13: ='Consumo Médio - Clientes'!AY10 -> 2658 | H13: 0 | I13: 0.01 | J13: 0 | K13: 0 | L13: 0 | M13: 0 | N13: 0 | O13: 0
A14: ='Consumo Médio - Clientes'!A11 -> Supermercado Bela Vista | B14: ='Consumo Médio - Clientes'!B11 -> 7009098124 | C14: ='Consumo Médio - Clientes'!C11 -> 3010494037 | D14: ='Consumo Médio - Clientes'!AX11 -> 13467 | E14: =F14/D14 -> 0.87194624 | F14: =SUM(H14*$H$2,I14*$I$2,J14*$J$2,$K$2*K14,$L$2*L14,M14*$M$2,N14*$N$2,O14*$O$2) -> 11742.5 | G14: ='Consumo Médio - Clientes'!AY11 -> 8076 | H14: 0 | I14: 0.025 | J14: 0 | K14: 0 | L14: 0 | M14: 0 | N14: 0 | O14: 0
A15: ='Consumo Médio - Clientes'!A12 -> Supermercado Tia Lia | B15: ='Consumo Médio - Clientes'!B12 -> 7005719624 | C15: ='Consumo Médio - Clientes'!C12 -> 3001268572 | D15: ='Consumo Médio - Clientes'!AX12 -> 3097 | E15: =F15/D15 -> 1.020371 | F15: =SUM(H15*$H$2,I15*$I$2,J15*$J$2,$K$2*K15,$L$2*L15,M15*$M$2,N15*$N$2,O15*$O$2) -> 3160.089 | G15: ='Consumo Médio - Clientes'!AY12 -> 0 | H15: 0.0423 | I15: 0 | J15: 0.1 | K15: 0 | L15: 0 | M15: 0.3 | N15: 0.3 | O15: 0.3
A16: ='Consumo Médio - Clientes'!A13 -> A M Lage | B16: ='Consumo Médio - Clientes'!B13 -> 7005623640 | C16: ='Consumo Médio - Clientes'!C13 -> 3002176022 | D16: ='Consumo Médio - Clientes'!AX13 -> 6475 | E16: =F16/D16 -> 0.72540541 | F16: =SUM(H16*$H$2,I16*$I$2,J16*$J$2,$K$2*K16,$L$2*L16,M16*$M$2,N16*$N$2,O16*$O$2) -> 4697 | G16: ='Consumo Médio - Clientes'!AY13 -> 8587 | H16: 0 | I16: 0.01 | J16: 0 | K16: 0 | L16: 0 | M16: 0 | N16: 0 | O16: 0
... A158: ='Consumo Médio - Clientes'!A155 -> Reis & Moraes Sociedade de Advogados | B158: ='Consumo Médio - Clientes'!B155 -> 7203052221 | C158: ='Consumo Médio - Clientes'!C155 -> 3000975425 | D158: ='Consumo Médio - Clientes'!AX155 -> 272 | E158: =F158/D158 -> 0.98216912 | F158: =SUM(H158*$H$2,I158*$I$2,J158*$J$2,$K$2*K158,$L$2*L158,M158*$M$2,N158*$N$2,O158*$O$2) -> 267.15 | G158: ='Consumo Médio - Clientes'!AY155 -> 0 | H158: 0.005 | I158: 0 | J158: 0 | K158: 0 | L158: 0 | M158: 0 | N158: 0 | O158: 0
A159: ='Consumo Médio - Clientes'!A156 -> Rafael Moraes Pereira | B159: ='Consumo Médio - Clientes'!B156 -> 0 | C159: ='Consumo Médio - Clientes'!C156 -> 3014002885 | D159: ='Consumo Médio - Clientes'!AX156 -> 627 | E159: =F159/D159 -> 0.85215311 | F159: =SUM(H159*$H$2,I159*$I$2,J159*$J$2,$K$2*K159,$L$2*L159,M159*$M$2,N159*$N$2,O159*$O$2) -> 534.3 | H159: 0.01 | I159: 0 | J159: 0 | K159: 0 | L159: 0 | M159: 0 | N159: 0 | O159: 0
A160: ='Consumo Médio - Clientes'!A157 -> Francisco Bernardes Texeira | B160: ='Consumo Médio - Clientes'!B157 -> 7002851665 | C160: ='Consumo Médio - Clientes'!C157 -> 3011864998 | D160: ='Consumo Médio - Clientes'!AX157 -> 110.66667 | E160: =F160/D160 -> 0.96560241 | F160: =SUM(H160*$H$2,I160*$I$2,J160*$J$2,$K$2*K160,$L$2*L160,M160*$M$2,N160*$N$2,O160*$O$2) -> 106.86 | H160: 0.002 | I160: 0 | J160: 0 | K160: 0 | L160: 0 | M160: 0 | N160: 0 | O160: 0
A161: ='Consumo Médio - Clientes'!A158 -> Glaucia Silva Oda | B161: ='Consumo Médio - Clientes'!B158 -> 0 | C161: ='Consumo Médio - Clientes'!C158 -> 3010214309 | D161: ='Consumo Médio - Clientes'!AX158 -> #DIV/0! | E161: =F161/D161 -> #DIV/0! | F161: =SUM(H161*$H$2,I161*$I$2,J161*$J$2,$K$2*K161,$L$2*L161,M161*$M$2,N161*$N$2,O161*$O$2) -> 0 | H161: 0 | I161: 0 | J161: 0 | K161: 0 | L161: 0 | M161: 0 | N161: 0 | O161: 0
A162: ='Consumo Médio - Clientes'!A159 -> Breno Denubila Almeida | B162: ='Consumo Médio - Clientes'!B159 -> 7201802268 | C162: ='Consumo Médio - Clientes'!C159 -> 3000811051 | D162: ='Consumo Médio - Clientes'!AX159 -> 564.66667 | E162: =F162/D162 -> 0.94622196 | F162: =SUM(H162*$H$2,I162*$I$2,J162*$J$2,$K$2*K162,$L$2*L162,M162*$M$2,N162*$N$2,O162*$O$2) -> 534.3 | G162: ='Consumo Médio - Clientes'!AY156 -> 0 | H162: 0.01 | I162: 0 | J162: 0 | K162: 0 | L162: 0 | M162: 0 | N162: 0 | O162: 0
F163: TOTAL | H163: =SUM(H5:H162) -> 1.037 | I163: =SUM(I5:I162) -> 0.5235 | J163: =SUM(J5:J162) -> 1 | K163: =SUM(K5:K162) -> 1 | L163: =SUM(L5:L162) -> 1 | M163: =SUM(M5:M162) -> 1 | N163: =SUM(N5:N162) -> 1 | O163: =SUM(O5:O162) -> 1

Sheet Consumo Médio - Clientes
A1: Cliente | B1: Nº Cliente | C1: UC | D1: 43617 | E1: 43647 | F1: 43678 | G1: 43709 | H1: 43739 | I1: 43770 | J1: 43800 | K1: 43831 | L1: 43862 | M1: 43891 | N1: 43922 | O1: 43952 | P1: 43983 | Q1: 44013 | R1: 44044 | S1: 44075 | T1: 44105 | U1: 44136 | V1: 44166 | W1: 44197 | X1: 44228 | Y1: 44256 | Z1: 44287 | AA1: 44317 | AB1: 44348 | AC1: 44378 | AD1: 44409 | AE1: 44440 | AF1: 44470 | AG1: 44501 | AH1: 44531 | AI1: 44562 | AJ1: 44593 | AK1: 44621 | AL1: 44652 | AM1: 44682 | AN1: 44713 | AO1: 44743 | AP1: 44774 | AQ1: 44805 | AR1: 44835 | AS1: 44866 | AT1: 44896 | AU1: 44927 | AV1: 44958 | AW1: 44986 | AX1: Média Trimestral | AY1: Saldo GD | AZ1: Competência | BA1: Vencimento | BB1: Faturar
A2: Lucile Confecções LTDA | B2: 7005713839 | C2: 3003858507 | D2: 1246 | E2: 1081 | F2: 1184 | G2: 1549 | H2: 2045 | I2: 4017 | J2: 2386 | K2: 4239 | L2: 2854 | M2: 3208 | N2: 1048 | O2: 1313 | P2: 1174 | Q2: 799 | R2: 952 | S2: 2085 | T2: 4218 | U2: 2922 | V2: 2964 | W2: 2806 | X2: 2186 | Y2: 1712 | Z2: 1123 | AA2: 1099 | AB2: 1881 | AC2: 1190 | AD2: 1279 | AE2: 3083 | AF2: 3273 | AG2: 2724 | AH2: 3490 | AI2: 3357 | AJ2: 3625 | AK2: 4187 | AL2: 3840 | AM2: 2478 | AN2: 817 | AO2: 601 | AP2: 638 | AQ2: 686 | AR2: 1216 | AS2: 1335 | AT2: 1317 | AU2: 2367 | AV2: 3056 | AW2: 3612 | AX2: 3308 | AY2: 0 | BE2: Jan | BF2: fev | BG2: Mar | BH2: Abr | BI2: Mai | BJ2: Jun | BK2: Jul | BL2: Ago | BM2: Set | BN2: Out | BO2: Nov | BP2: Dez
A3: CLL Hotel e Turismo | B3: 7008528502 | C3: 3001084033 | D3: 7160 | E3: 6520 | F3: 6840 | G3: 7440 | H3: 6920 | I3: 6920 | J3: 7240 | K3: 6560 | L3: 7440 | M3: 7440 | N3: 5640 | O3: 4880 | P3: 5080 | Q3: 4840 | R3: 6520 | S3: 6120 | T3: 5720 | U3: 7480 | V3: 6680 | W3: 6680 | X3: 5680 | Y3: 5760 | Z3: 3760 | AA3: 4280 | AB3: 5800 | AC3: 5480 | AD3: 5480 | AE3: 5280 | AF3: 5760 | AG3: 5560 | AH3: 6600 | AI3: 6400 | AJ3: 7160 | AK3: 6960 | AL3: 7080 | AM3: 6800 | AN3: 6760 | AO3: 6280 | AP3: 5560 | AQ3: 6360 | AR3: 7440 | AS3: 7240 | AT3: 7960 | AU3: 5880 | AV3: 7560 | AW3: 7640 | AX3: 7707 | AY3: 19766 | AZ3: Abril | BA3: 45049 | BB3: 45036 | BC3: Usina - Fazenda Vale do Sol | BD3: 3013497957 | BE3: 53904 | BF3: 52408 | BG3: 52317 | BH3: 48122 | BI3: 50739 | BJ3: 48737 | BK3: 52874 | BL3: 56271 | BM3: 51096 | BN3: 53430 | BO3: 45995 | BP3: 51054
A4: Academia Planeta Corpo | B4: 7005369021 | C4: 3011373971 | D4: 440 | E4: 600 | F4: 680 | G4: 760 | H4: 560 | I4: 520 | J4: 320 | K4: 440 | L4: 280 | M4: 320 | N4: 440 | O4: 0 | P4: 0 | Q4: 0 | R4: 0 | S4: 320 | T4: 280 | U4: 360 | V4: 280 | W4: 400 | X4: 320 | Y4: 280 | Z4: 0 | AA4: 400 | AB4: 480 | AC4: 480 | AD4: 600 | AE4: 560 | AF4: 480 | AG4: 560 | AH4: 480 | AI4: 480 | AJ4: 440 | AK4: 560 | AL4: 560 | AM4: 680 | AN4: 840 | AO4: 800 | AP4: 760 | AQ4: 840 | AR4: 920 | AS4: 360 | AT4: 680 | AU4: 800 | AV4: 480 | AW4: 440 | AX4: 467 | AY4: 1359 | AZ4: Abril | BA4: 45063 | BB4: 45044
A5: MD Predial | B5: 7005492088 | C5: 3001449459 | D5: 960 | E5: 920 | F5: 1120 | G5: 1040 | H5: 1120 | I5: 1240 | J5: 1000 | K5: 1120 | L5: 1200 | M5: 1360 | N5: 1080 | O5: 1040 | P5: 1320 | Q5: 960 | R5: 1240 | S5: 1280 | T5: 1480 | U5: 1320 | V5: 1400 | W5: 1160 | X5: 960 | Y5: 1000 | Z5: 1160 | AA5: 960 | AB5: 960 | AC5: 1000 | AD5: 1040 | AE5: 1160 | AF5: 840 | AG5: 760 | AH5: 720 | AI5: 720 | AJ5: 720 | AK5: 720 | AL5: 800 | AM5: 800 | AN5: 720 | AO5: 880 | AP5: 680 | AQ5: 800 | AR5: 1000 | AS5: 840 | AT5: 880 | AU5: 840 | AV5: 760 | AX5: 1440 | AY5: 0
A6: MD Predial | B6: 7005492088 | C6: 3011504476 | D6: 1560 | E6: 1280 | F6: 1360 | G6: 1680 | H6: 1680 | I6: 2920 | J6: 1960 | K6: 2280 | L6: 2480 | M6: 2240 | N6: 1480 | O6: 1280 | P6: 1240 | Q6: 1160 | R6: 1360 | S6: 1400 | T6: 2480 | U6: 2320 | V6: 3320 | W6: 2640 | X6: 2160 | Y6: 2120 | Z6: 2320 | AA6: 1520 | AB6: 1640 | AC6: 1200 | AD6: 1200 | AE6: 2040 | AF6: 2040 | AG6: 2080 | AH6: 2280 | AI6: 2600 | AJ6: 2520 | AK6: 3240 | AL6: 2960 | AM6: 1840 | AN6: 1600 | AO6: 1480 | AP6: 1440 | AQ6: 1720 | AR6: 2280 | AS6: 2000 | AT6: 2160 | AU6: 2120 | AV6: 2680 | AW6: 1589 | AX6: 1867 | AY6: 127
A7: MD Predial | B7: 7005492088 | C7: 3014340686 | T7: 3388 | U7: 3162 | V7: 2869 | W7: 3865 | X7: 2686 | Y7: 2154 | Z7: 2233 | AA7: 2095 | AB7: 1581 | AC7: 2146 | AD7: 2397 | AE7: 2247 | AF7: 1782 | AG7: 1670 | AH7: 1720 | AI7: 1677 | AJ7: 1812 | AK7: 1870 | AL7: 1995 | AM7: 2283 | AN7: 1309 | AO7: 1829 | AP7: 1449 | AQ7: 1792 | AR7: 1559 | AS7: 1660 | AT7: 1639 | AU7: 1635 | AV7: 1558 | AW7: 1406 | AX7: 1447 | AY7: 0
A8: Fazenda Terra Mirante | B8: 7202158396 | C8: 3002906325 | I8: 404 | J8: 297 | K8: 358 | L8: 315 | M8: 322 | N8: 340 | O8: 340 | P8: 401 | Q8: 307 | R8: 402 | S8: 347 | T8: 457 | U8: 350 | V8: 350 | W8: 350 | X8: 350 | Y8: 350 | Z8: 433 | AA8: 402 | AB8: 417 | AC8: 407 | AD8: 454 | AE8: 373 | AF8: 411 | AG8: 720 | AH8: 387 | AI8: 387 | AJ8: 377 | AK8: 462 | AL8: 374 | AM8: 351 | AN8: 413 | AO8: 358 | AP8: 344 | AQ8: 429 | AR8: 407 | AS8: 389 | AT8: 434 | AU8: 389 | AV8: 375 | AW8: 404 | AX8: 388 | AY8: 0
A9: Irmãs Martins Andrade LTDA-ME | B9: 7005723073 | C9: 3002906806 | D9: 2263 | E9: 1989 | F9: 2277 | G9: 2031 | H9: 1941 | I9: 2268 | J9: 2117 | K9: 2058 | L9: 2364 | M9: 2129 | N9: 1606 | O9: 1762 | P9: 1730 | Q9: 1587 | R9: 1999 | S9: 1958 | T9: 2118 | U9: 2132 | V9: 1331 | W9: 2162 | X9: 1983 | Y9: 2200 | Z9: 2071 | AA9: 1894 | AB9: 2236 | AC9: 1987 | AD9: 2075 | AE9: 2317 | AF9: 2086 | AG9: 2202 | AH9: 2036 | AI9: 1910 | AJ9: 2143 | AK9: 2219 | AL9: 1944 | AM9: 2110 | AN9: 2194 | AO9: 2072 | AP9: 1989 | AQ9: 2421 | AR9: 2164 | AS9: 2064 | AT9: 2353 | AU9: 2152 | AV9: 2098 | AW9: 2393 | AX9: 2262 | AY9: 4764 | AZ9: Abril | BA9: 45063 | BB9: 45044
A10: Supermercado Bela Vista | B10: 7009098124 | C10: 3003388708 | D10: 5830 | E10: 4757 | F10: 4753 | G10: 5481 | H10: 5249 | I10: 6055 | J10: 5647 | K10: 6105 | L10: 6355 | M10: 6094 | N10: 5388 | O10: 6589 | P10: 5750 | Q10: 5874 | R10: 6723 | S10: 5634 | T10: 6380 | U10: 7074 | V10: 6620 | W10: 7928 | X10: 6492 | Y10: 6326 | Z10: 7223 | AA10: 5740 | AB10: 5617 | AC10: 5318 | AD10: 5797 | AE10: 5391 | AF10: 6048 | AG10: 5196 | AH10: 4642 | AI10: 5976 | AJ10: 5269 | AK10: 4911 | AL10: 5180 | AM10: 4998 | AN10: 4687 | AO10: 4880 | AP10: 4113 | AQ10: 4492 | AR10: 4935 | AS10: 4949 | AT10: 5240 | AU10: 5156 | AV10: 5311 | AW10: 5642 | AX10: 5293 | AY10: 2658 | AZ10: Abril | BA10: 45039 | BB10: 45027
A11: Supermercado Bela Vista | B11: 7009098124 | C11: 3010494037 | D11: 3320 | E11: 2840 | F11: 3000 | G11: 2880 | H11: 2600 | I11: 3360 | J11: 3000 | K11: 3200 | L11: 3280 | M11: 1560 | N11: 800 | O11: 920 | P11: 0 | Q11: 0 | R11: 0 | S11: 0 | T11: 0 | U11: 0 | V11: 0 | W11: 0 | X11: 0 | Y11: 0 | Z11: 0 | AA11: 0 | AB11: 0 | AC11: 0 | AD11: 1080 | AE11: 12320 | AF11: 15800 | AG11: 14120 | AH11: 15280 | AI11: 4880 | AJ11: 26960 | AK11: 13680 | AL11: 14040 | AM11: 13520 | AN11: 11880 | AO11: 12360 | AP11: 10520 | AQ11: 10920 | AR11: 11520 | AS11: 12200 | AT11: 14080 | AU11: 15600 | AV11: 12640 | AW11: 14880 | AX11: 13467 | AY11: 8076 | AZ11: Abril | BA11: 45039 | BB11: 45027
A12: Supermercado Tia Lia | B12: 7005719624 | C12: 3001268572 | D12: 4590 | E12: 3124 | F12: 4253 | G12: 3269 | H12: 3414 | I12: 3814 | J12: 3437 | K12: 3922 | L12: 4078 | M12: 4227 | N12: 4622 | O12: 3755 | P12: 3643 | Q12: 3284 | R12: 3940 | S12: 3522 | T12: 1700 | U12: 1700 | V12: 1700 | W12: 1700 | X12: 1700 | Y12: 1700 | Z12: 1700 | AA12: 1700 | AB12: 3969 | AC12: 3557 | AD12: 3789 | AE12: 4493 | AF12: 4292 | AG12: 4059 | AH12: 4214 | AI12: 4377 | AJ12: 4185 | AK12: 4195 | AL12: 4522 | AM12: 4187 | AN12: 4519 | AO12: 4038 | AP12: 4312 | AQ12: 4400 | AR12: 4364 | AS12: 4073 | AT12: 4677 | AU12: 4585 | AV12: 4276 | AX12: 3097 | AY12: 0
A13: A M Lage | B13: 7005623640 | C13: 3002176022 | D13: 6392 | E13: 6030 | F13: 6554 | G13: 7210 | H13: 8151 | I13: 9324 | J13: 7625 | K13: 9372 | L13: 7768 | M13: 7818 | N13: 5646 | O13: 4484 | P13: 4853 | Q13: 5044 | R13: 5315 | S13: 5749 | T13: 8479 | U13: 7719 | V13: 7737 | W13: 9244 | X13: 8300 | Y13: 7206 | Z13: 7512 | AA13: 6695 | AB13: 6704 | AC13: 6486 | AD13: 6130 | AE13: 7771 | AF13: 8228 | AG13: 6255 | AH13: 6377 | AI13: 6163 | AJ13: 6120 | AK13: 6394 | AL13: 6484 | AM13: 5759 | AN13: 6007 | AO13: 5273 | AP13: 5917 | AQ13: 6615 | AR13: 6858 | AS13: 6276 | AT13: 7010 | AU13: 6369 | AV13: 6131 | AW13: 7062 | AX13: 6475 | AY13: 8587
